Workbook

Sheet Input
A1: Name Of Company | B1: Quantum Innovation
A2: Start Date of Business | B2: 45017
A4: Operational Details
A5: Annual Capacity | B5: 120000 | C5: Units
A6: Utilisation Rate | B6: 0.48 | C6: Percent
A7: Annual Increase | B7: 0.03 | C7: Percent
A8: Units Sold (as % of available units) | B8: 0.6 | C8: Percent
A9: Annual Increase | B9: 0.03 | C9: Percent
A11: Selling price per unit | B11: 1000 | C11: Rs.
A12: Annual growth rate | B12: 0.09 | C12: Percent
A13: Raw material per unit | B13: 480 | C13: Rs.
A14: Annual growth rate | B14: 0.05 | C14: Percent
A15: Labor per unit | B15: 230 | C15: Rs.
A16: Annual growth rate | B16: 0.07 | C16: Percent
A18: Selling, General and admin expenses | B18: 1600000 | C18: Rs.
... A20: Commission on sales | B20: 0.1 | C20: Percent
A22: Capital Structure
A23: Equity
A24: Promoter 1 | B24: 400000 | C24: Rs.
A25: Promoter 2 | B25: 400000 | C25: Rs.
A26: Promoter 3 | B26: 400000 | C26: Rs.
A27: Promoter 4 | B27: 400000 | C27: Rs.
A28: Total | B28: 1600000 | C28: Rs.
A30: Authorised Capital
A31: Authorised number of shares | B31: 200000 | C31: NoS.
A32: Face Value per share | B32: 10 | C32: Rs.
A33: Authorised Capital | B33: =B31*B32 -> 2000000
A35: Debt
A36: Loan | B36: 1500000 | C36: Rs.
A37: Default rate of Interest | B37: 0.12 | C37: Percent
A38: Penal rate of interest | B38: 0.15 | C38: Percent
A39: Penalty levied when int. coverage ratio is below | B39: 30
A40: Loan Moratorium period | B40: 1 | C40: Year
A41: Loan repayment period (equal installments) | B41: 4 | C41: Years
A43: Capital expenditure
A44: Equipment
A45: 2023 | B45: 1500000 | C45: Rs.
A46: 2026 | B46: 500000 | C46: Rs.
A47: Depreciation Rate | B47: 0.15 | C47: percent
A49: Building
...

Sheet Revenue
A1: Particulars | C1: 0 | D1: =C1+1 -> 1 | E1: =D1+1 -> 2 | F1: =E1+1 -> 3 | G1: =F1+1 -> 4 | H1: =G1+1 -> 5
A2: Year ending | D2: =EOMONTH(Input!B2,11) -> 45382 | E2: =EOMONTH(D2,12) -> 45747 | F2: =EOMONTH(E2,12) -> 46112 | G2: =EOMONTH(F2,12) -> 46477 | H2: =EOMONTH(G2,12) -> 46843
A4: Annual Production capacity | B4: Units | D4: =Input!$B$5 -> 120000 | E4: =Input!$B$5 -> 120000 | F4: =Input!$B$5 -> 120000 | G4: =Input!$B$5 -> 120000 | H4: =Input!$B$5 -> 120000
A5: Capacity utilisation | B5: Percentage | D5: =MAX(Input!$B$6,Revenue!C5+Input!$B$7) -> 0.48 | E5: =MAX(Input!$B$6,Revenue!D5+Input!$B$7) -> 0.51 | F5: =MAX(Input!$B$6,Revenue!E5+Input!$B$7) -> 0.54 | G5: =MAX(Input!$B$6,Revenue!F5+Input!$B$7) -> 0.57 | H5: =MAX(Input!$B$6,Revenue!G5+Input!$B$7) -> 0.6
A6: Total Production | B6: Units | D6: =D4*D5 -> 57600 | E6: =E4*E5 -> 61200 | F6: =F4*F5 -> 64800 | G6: =G4*G5 -> 68400 | H6: =H4*H5 -> 72000
A8: Units Sold (as % of available units) | B8: % | D8: =MAX(Input!$B$8,Revenue!C8+Input!$B$9) -> 0.6 | E8: =MAX(Input!$B$8,Revenue!D8+Input!$B$9) -> 0.63 | F8: =MAX(Input!$B$8,Revenue!E8+Input!$B$9) -> 0.66 | G8: =MAX(Input!$B$8,Revenue!F8+Input!$B$9) -> 0.69 | H8: =MAX(Input!$B$8,Revenue!G8+Input!$B$9) -> 0.72
A10: Units available
A11: Opening stock | B11: Units | E11: =D15 -> 23040 | F11: =E15 -> 31168.8 | G11: =F15 -> 32629.392 | H11: =G15 -> 31319.112
A12: Add: Production | B12: Units | D12: =D6 -> 57600 | E12: =E6 -> 61200 | F12: =F6 -> 64800 | G12: =G6 -> 68400 | H12: =H6 -> 72000
A13: Available Units | B13: Units | D13: =SUM(D11:D12) -> 57600 | E13: =SUM(E11:E12) -> 84240 | F13: =SUM(F11:F12) -> 95968.8 | G13: =SUM(G11:G12) -> 101029.39 | H13: =SUM(H11:H12) -> 103319.11
A14: Units sold | B14: Units | D14: =D13*D8 -> 34560 | E14: =E13*E8 -> 53071.2 | F14: =F13*F8 -> 63339.408 | G14: =G13*G8 -> 69710.28 | H14: =H13*H8 -> 74389.76
A15: Closing stock | B15: Units | D15: =D13-D14 -> 23040 | E15: =E13-E14 -> 31168.8 | F15: =F13-F14 -> 32629.392 | G15: =G13-G14 -> 31319.112 | H15: =H13-H14 -> 28929.351
A17: Selling price per unit | B17: Rs. | D17: =MAX(Input!$B$11,Revenue!C17*(1+Input!$B$12)) -> 1000 | E17: =MAX(Input!$B$11,Revenue!D17*(1+Input!$B$12)) -> 1090 | F17: =MAX(Input!$B$11,Revenue!E17*(1+Input!$B$12)) -> 1188.1 | G17: =MAX(Input!$B$11,Revenue!F17*(1+Input!$B$12)) -> 1295.029 | H17: =MAX(Input!$B$11,Revenue!G17*(1+Input!$B$12)) -> 1411.5816
A18: Revenue | B18: Rs. | D18: =D17*D14 -> 34560000 | E18: =E17*E14 -> 57847608 | F18: =F17*F14 -> 75253551 | G18: =G17*G14 -> 90276835 | H18: =H17*H14 -> 1.0500722e+08
A20: COGS
A21: Cost of production
A22: Material/unit | B22: Rs. | D22: =MAX(C22*(1+Input!$B$14),Input!$B$13) -> 480 | E22: =MAX(D22*(1+Input!$B$14),Input!$B$13) -> 504 | F22: =MAX(E22*(1+Input!$B$14),Input!$B$13) -> 529.2 | G22: =MAX(F22*(1+Input!$B$14),Input!$B$13) -> 555.66 | H22: =MAX(G22*(1+Input!$B$14),Input!$B$13) -> 583.443
A23: Labour/unit | B23: Rs. | D23: =MAX(C23*(1+Input!$B$16),Input!$B$15) -> 230 | E23: =MAX(D23*(1+Input!$B$16),Input!$B$15) -> 246.1 | F23: =MAX(E23*(1+Input!$B$16),Input!$B$15) -> 263.327 | G23: =MAX(F23*(1+Input!$B$16),Input!$B$15) -> 281.75989 | H23: =MAX(G23*(1+Input!$B$16),Input!$B$15) -> 301.48308
A25: Opening stock | D25: =C27 -> 0 | E25: =D27 -> 16358400 | F25: =E27 -> 23379717 | G25: =F27 -> 25859674 | H25: =G27 -> 26227247
A26: Total cost of production | B26: Rs. | D26: =SUM(D22:D23)*D6 -> 40896000 | E26: =SUM(E22:E23)*E6 -> 45906120 | F26: =SUM(F22:F23)*F6 -> 51355750 | G26: =SUM(G22:G23)*G6 -> 57279520 | H26: =SUM(H22:H23)*H6 -> 63714678
A27: Less: Closing Stock | D27: =D15*(SUM(D22:D23)) -> 16358400 | E27: =E15*(SUM(E22:E23)) -> 23379717 | F27: =F15*(SUM(F22:F23)) -> 25859674 | G27: =G15*(SUM(G22:G23)) -> 26227247 | H27: =H15*(SUM(H22:H23)) -> 25600337
A28: Cost of goods sold | D28: =D25+D26-D27 -> 24537600 | E28: =E25+E26-E27 -> 38884803 | F28: =F25+F26-F27 -> 48875792 | G28: =G25+G26-G27 -> 56911948 | H28: =H25+H26-H27 -> 64341587

Sheet P&L
A1: Particulars | C1: 0 | D1: =C1+1 -> 1 | E1: =D1+1 -> 2 | F1: =E1+1 -> 3 | G1: =F1+1 -> 4 | H1: =G1+1 -> 5
A2: Year ending | D2: =EOMONTH(Input!B2,11) -> 45382 | E2: =EOMONTH(D2,12) -> 45747 | F2: =EOMONTH(E2,12) -> 46112 | G2: =EOMONTH(F2,12) -> 46477 | H2: =EOMONTH(G2,12) -> 46843
A3: =Revenue!A18 -> Revenue | B3: =Revenue!B18 -> Rs. | C3: =Revenue!C18 -> 0 | D3: =Revenue!D18 -> 34560000 | E3: =Revenue!E18 -> 57847608 | F3: =Revenue!F18 -> 75253551 | G3: =Revenue!G18 -> 90276835 | H3: =Revenue!H18 -> 1.0500722e+08
A4: Less: COGS | B4: Rs. | C4: =Revenue!C28 -> 0 | D4: =Revenue!D28 -> 24537600 | E4: =Revenue!E28 -> 38884803 | F4: =Revenue!F28 -> 48875792 | G4: =Revenue!G28 -> 56911948 | H4: =Revenue!H28 -> 64341587
A5: Gross Profit | B5: Rs. | D5: =D3-D4 -> 10022400 | E5: =E3-E4 -> 18962805 | F5: =F3-F4 -> 26377758 | G5: =G3-G4 -> 33364887 | H5: =H3-H4 -> 40665630
A6: Less: Indirect Cost | B6: Rs.
A7: Commission on sales | B7: Rs. | D7: =D3*Input!$B$20 -> 3456000 | E7: =E3*Input!$B$20 -> 5784760.8 | F7: =F3*Input!$B$20 -> 7525355.1 | G7: =G3*Input!$B$20 -> 9027683.5 | H7: =H3*Input!$B$20 -> 10500722
A8: Selling, general and admin expenses | B8: Rs. | D8: =MAX(Input!$B$18,'P&L'!C8*(1+Input!$B$19)) -> 1600000 | E8: =MAX(Input!$B$18,'P&L'!D8*(1+Input!$B$19)) -> 1696000 | F8: =MAX(Input!$B$18,'P&L'!E8*(1+Input!$B$19)) -> 1797760 | G8: =MAX(Input!$B$18,'P&L'!F8*(1+Input!$B$19)) -> 1905625.6 | H8: =MAX(Input!$B$18,'P&L'!G8*(1+Input!$B$19)) -> 2019963.1
A9: Total indirect cost | B9: Rs. | D9: =SUM(D7:D8) -> 5056000 | E9: =SUM(E7:E8) -> 7480760.8 | F9: =SUM(F7:F8) -> 9323115.1 | G9: =SUM(G7:G8) -> 10933309 | H9: =SUM(H7:H8) -> 12520685
A10: EBITDA | B10: Rs. | D10: =D5-D9 -> 4966400 | E10: =E5-E9 -> 11482044 | F10: =F5-F9 -> 17054643 | G10: =G5-G9 -> 22431578 | H10: =H5-H9 -> 28144945
A11: Less: Dep. And Amortization | B11: Rs. | D11: =SUM('Fixed Assets'!D10,'Fixed Assets'!D19,'Fixed Assets'!D28) -> 245000 | E11: =SUM('Fixed Assets'!E10,'Fixed Assets'!E19,'Fixed Assets'!E28) -> 245000 | F11: =SUM('Fixed Assets'!F10,'Fixed Assets'!F19,'Fixed Assets'!F28) -> 320000 | G11: =SUM('Fixed Assets'!G10,'Fixed Assets'!G19,'Fixed Assets'!G28) -> 320000 | H11: =SUM('Fixed Assets'!H10,'Fixed Assets'!H19,'Fixed Assets'!H28) -> 320000
A12: EBIT | B12: Rs. | D12: =D10-D11 -> 4721400 | E12: =E10-E11 -> 11237044 | F12: =F10-F11 -> 16734643 | G12: =G10-G11 -> 22111578 | H12: =H10-H11 -> 27824945
A13: Less: Interest expenses | B13: Rs. | D13: =IF('Debt Schedule'!D11<Input!$B$39,'Debt Schedule'!D9,'Debt Schedule'!D8) -> 225000 | E13: =IF('Debt Schedule'!E11<Input!$B$39,'Debt Schedule'!E9,'Debt Schedule'!E8) -> 135000 | F13: =IF('Debt Schedule'!F11<Input!$B$39,'Debt Schedule'!F9,'Debt Schedule'!F8) -> 90000 | G13: =IF('Debt Schedule'!G11<Input!$B$39,'Debt Schedule'!G9,'Debt Schedule'!G8) -> 45000 | H13: =IF('Debt Schedule'!H11<Input!$B$39,'Debt Schedule'!H9,'Debt Schedule'!H8) -> 0
A14: EBT | B14: Rs. | D14: =D12-D13 -> 4496400 | E14: =E12-E13 -> 11102044 | F14: =F12-F13 -> 16644643 | G14: =G12-G13 -> 22066578 | H14: =H12-H13 -> 27824945
A15: Less: Income tax | B15: Rs. | D15: =D14*Input!$B$57 -> 1348920 | E15: =E14*Input!$B$57 -> 3330613.2 | F15: =F14*Input!$B$57 -> 4993393 | G15: =G14*Input!$B$57 -> 6619973.4 | H15: =H14*Input!$B$57 -> 8347483.6
A16: EAT | B16: Rs. | D16: =D14-D15 -> 3147480 | E16: =E14-E15 -> 7771430.9 | F16: =F14-F15 -> 11651250 | G16: =G14-G15 -> 15446605 | H16: =H14-H15 -> 19477462
A17: Net margin | B17: Rs. | D17: =D16/D3 -> 0.091072917 | E17: =E16/E3 -> 0.13434317 | F17: =F16/F3 -> 0.15482659 | G17: =G16/G3 -> 0.17110264 | H17: =H16/H3 -> 0.18548689
A18: Less: Dividend paid | B18: Rs. | D18: =IF(D17>12%,Input!$B$66*'P&L'!D16,0) -> 0 | E18: =IF(E17>12%,Input!$B$66*'P&L'!E16,0) -> 2720000.8 | F18: =IF(F17>12%,Input!$B$66*'P&L'!F16,0) -> 4077937.6 | G18: =IF(G17>12%,Input!$B$66*'P&L'!G16,0) -> 5406311.6 | H18: =IF(H17>12%,Input!$B$66*'P&L'!H16,0) -> 6817111.6
A19: Transfer to reserves | B19: Rs. | D19: =D16-D18 -> 3147480 | E19: =E16-E18 -> 5051430.1 | F19: =F16-F18 -> 7573312.7 | G19: =G16-G18 -> 10040293 | H19: =H16-H18 -> 12660350

Sheet Fixed Assets
A1: Particulars | C1: 0 | D1: =C1+1 -> 1 | E1: =D1+1 -> 2 | F1: =E1+1 -> 3 | G1: =F1+1 -> 4 | H1: =G1+1 -> 5
A2: Year ending | D2: =EOMONTH(Input!B2,11) -> 45382 | E2: =EOMONTH(D2,12) -> 45747 | F2: =EOMONTH(E2,12) -> 46112 | G2: =EOMONTH(F2,12) -> 46477 | H2: =EOMONTH(G2,12) -> 46843
A3: Equipment
A4: Opening balance | B4: Rs. | D4: =C7 -> 0 | E4: =D7 -> 1500000 | F4: =E7 -> 1500000 | G4: =F7 -> 2000000 | H4: =G7 -> 2000000
A5: Add: Purchases | B5: Rs. | D5: =Input!B45 -> 1500000 | E5: 0 | F5: =Input!$B$46 -> 500000
A6: Less: Sales | B6: Rs. | D6: 0 | E6: 0
A7: Gross block | B7: Rs. | D7: =D4+D5-D6 -> 1500000 | E7: =E4+E5-E6 -> 1500000 | F7: =F4+F5-F6 -> 2000000 | G7: =G4+G5-G6 -> 2000000 | H7: =H4+H5-H6 -> 2000000
A8: Less: Accumulated depreciation | B8: Rs. | D8: =D7*Input!$B$47 -> 225000 | E8: =E7*Input!$B$47+D8 -> 450000 | F8: =F7*Input!$B$47+E8 -> 750000 | G8: =G7*Input!$B$47+F8 -> 1050000 | H8: =H7*Input!$B$47+G8 -> 1350000
A9: Net block | B9: Rs. | D9: =D7-D8 -> 1275000 | E9: =E7-E8 -> 1050000 | F9: =F7-F8 -> 1250000 | G9: =G7-G8 -> 950000 | H9: =H7-H8 -> 650000
A10: Depreciation for the year | D10: =D8-C8 -> 225000 | E10: =E8-D8 -> 225000 | F10: =F8-E8 -> 300000 | G10: =G8-F8 -> 300000 | H10: =H8-G8 -> 300000
A12: Building
A13: Opening balance | B13: Rs. | D13: =C16 -> 0 | E13: =D16 -> 200000 | F13: =E16 -> 200000 | G13: =F16 -> 200000 | H13: =G16 -> 200000
A14: Add: Purchases | B14: Rs. | D14: =Input!$B$50 -> 200000 | E14: 0 | F14: 0
A15: Less: Sales | B15: Rs. | D15: 0 | E15: 0
A16: Gross block | B16: Rs. | D16: =D13+D14-D15 -> 200000 | E16: =E13+E14-E15 -> 200000 | F16: =F13+F14-F15 -> 200000 | G16: =G13+G14-G15 -> 200000 | H16: =H13+H14-H15 -> 200000
A17: Less: Accumulated depreciation | B17: Rs. | D17: =D16*Input!$B$51+C17 -> 20000 | E17: =E16*Input!$B$51+D17 -> 40000 | F17: =F16*Input!$B$51+E17 -> 60000 | G17: =G16*Input!$B$51+F17 -> 80000 | H17: =H16*Input!$B$51+G17 -> 100000
A18: Net block | B18: Rs. | D18: =D16-D17 -> 180000 | E18: =E16-E17 -> 160000 | F18: =F16-F17 -> 140000 | G18: =G16-G17 -> 120000 | H18: =H16-H17 -> 100000
A19: Depreciation for the year | D19: =D17-C17 -> 20000 | E19: =E17-D17 -> 20000 | F19: =F17-E17 -> 20000 | G19: =G17-F17 -> 20000 | H19: =H17-G17 -> 20000
A21: Land
A22: Opening balance | B22: Rs. | D22: =C25 -> 0 | E22: =D25 -> 800000 | F22: =E25 -> 800000 | G22: =F25 -> 800000 | H22: =G25 -> 800000
A23: Add: Purchases | B23: Rs. | D23: =Input!$B$54 -> 800000 | E23: 0 | F23: 0
A24: Less: Sales | B24: Rs. | D24: 0 | E24: 0
A25: Gross block | B25: Rs. | D25: =D22+D23-D24 -> 800000 | E25: =E22+E23-E24 -> 800000 | F25: =F22+F23-F24 -> 800000 | G25: =G22+G23-G24 -> 800000 | H25: =H22+H23-H24 -> 800000
A26: Less: Accumulated depreciation | B26: Rs. | D26: =D25*Input!$B$55+C26 -> 0 | E26: =E25*Input!$B$55+D26 -> 0 | F26: =F25*Input!$B$55+E26 -> 0 | G26: =G25*Input!$B$55+F26 -> 0 | H26: =H25*Input!$B$55+G26 -> 0
A27: Net block | B27: Rs. | D27: =D25-D26 -> 800000 | E27: =E25-E26 -> 800000 | F27: =F25-F26 -> 800000 | G27: =G25-G26 -> 800000 | H27: =H25-H26 -> 800000
A28: Depreciation for the year | D28: =D26-C26 -> 0 | E28: =E26-D26 -> 0 | F28: =F26-E26 -> 0 | G28: =G26-F26 -> 0 | H28: =H26-G26 -> 0

Sheet Debt Schedule
A1: Particulars | C1: 0 | D1: =C1+1 -> 1 | E1: =D1+1 -> 2 | F1: =E1+1 -> 3 | G1: =F1+1 -> 4 | H1: =G1+1 -> 5
A2: Year ending | D2: =EOMONTH(Input!B2,11) -> 45382 | E2: =EOMONTH(D2,12) -> 45747 | F2: =EOMONTH(E2,12) -> 46112 | G2: =EOMONTH(F2,12) -> 46477 | H2: =EOMONTH(G2,12) -> 46843
A3: Opening balance | D3: =C6 -> 0 | E3: =D6 -> 1500000 | F3: =E6 -> 1125000 | G3: =F6 -> 750000 | H3: =G6 -> 375000
A4: Add: Loan taken | D4: =Input!$B$36 -> 1500000
A5: Less: Loan repaid | D5: =IF(AND(COUNT($D$1:D1)>Input!$B$40,COUNT($D$1:D1)<=5),Input!$B$36/Input!$B$41,0) -> 0 | E5: =IF(AND(COUNT($D$1:E1)>Input!$B$40,COUNT($D$1:E1)<=5),Input!$B$36/Input!$B$41,0) -> 375000 | F5: =IF(AND(COUNT($D$1:F1)>Input!$B$40,COUNT($D$1:F1)<=5),Input!$B$36/Input!$B$41,0) -> 375000 | G5: =IF(AND(COUNT($D$1:G1)>Input!$B$40,COUNT($D$1:G1)<=5),Input!$B$36/Input!$B$41,0) -> 375000 | H5: =IF(AND(COUNT($D$1:H1)>Input!$B$40,COUNT($D$1:H1)<=5),Input!$B$36/Input!$B$41,0) -> 375000
A6: Closing Balance | D6: =D3+D4-D5 -> 1500000 | E6: =E3+E4-E5 -> 1125000 | F6: =F3+F4-F5 -> 750000 | G6: =G3+G4-G5 -> 375000 | H6: =H3+H4-H5 -> 0
A8: Interest expenses @12% | D8: =D6*Input!$B$37 -> 180000 | E8: =E6*Input!$B$37 -> 135000 | F8: =F6*Input!$B$37 -> 90000 | G8: =G6*Input!$B$37 -> 45000 | H8: =H6*Input!$B$37 -> 0
A9: Interest expenses @15% | D9: =D6*Input!$B$38 -> 225000 | E9: =E6*Input!$B$38 -> 168750 | F9: =F6*Input!$B$38 -> 112500 | G9: =G6*Input!$B$38 -> 56250 | H9: =H6*Input!$B$38 -> 0
A11: Interest coverage ratio | D11: =IFERROR('P&L'!D12/'Debt Schedule'!D8,"NA") -> 26.23 | E11: =IFERROR('P&L'!E12/'Debt Schedule'!E8,"NA") -> 83.237364 | F11: =IFERROR('P&L'!F12/'Debt Schedule'!F8,"NA") -> 185.94048 | G11: =IFERROR('P&L'!G12/'Debt Schedule'!G8,"NA") -> 491.3684 | H11: =IFERROR('P&L'!H12/'Debt Schedule'!H8,"NA") -> NA
A12: EBIT/Interest

Sheet Working Capital
A1: Particulars | C1: 0 | D1: =C1+1 -> 1 | E1: =D1+1 -> 2 | F1: =E1+1 -> 3 | G1: =F1+1 -> 4 | H1: =G1+1 -> 5
A2: Year ending | D2: =EOMONTH(Input!B2,11) -> 45382 | E2: =EOMONTH(D2,12) -> 45747 | F2: =EOMONTH(E2,12) -> 46112 | G2: =EOMONTH(F2,12) -> 46477 | H2: =EOMONTH(G2,12) -> 46843
A3: Current assets
A4: Debtors | D4: ='P&L'!D3/365*D5 -> 3787397.3 | E4: ='P&L'!E3/365*E5 -> 6022490.7 | F4: ='P&L'!F3/365*F5 -> 7422268 | G4: ='P&L'!G3/365*G5 -> 8409349 | H4: ='P&L'!H3/365*H5 -> 9206112.2
A5: Debtor Days | D5: =IF(D$1=1,Input!$B$60,MIN('Working Capital'!C5-Input!$B$61,Input!$B$60)) -> 40 | E5: =IF(E$1=1,Input!$B$60,MIN('Working Capital'!D5-Input!$B$61,Input!$B$60)) -> 38 | F5: =IF(F$1=1,Input!$B$60,MIN('Working Capital'!E5-Input!$B$61,Input!$B$60)) -> 36 | G5: =IF(G$1=1,Input!$B$60,MIN('Working Capital'!F5-Input!$B$61,Input!$B$60)) -> 34 | H5: =IF(H$1=1,Input!$B$60,MIN('Working Capital'!G5-Input!$B$61,Input!$B$60)) -> 32
A7: Current Liabilities
A8: Creditors | D8: =(Revenue!D22*Revenue!D6)/365*D9 -> 4923616.4 | E8: =(Revenue!E22*Revenue!E6)/365*E9 -> 5746428.5 | F8: =(Revenue!F22*Revenue!F6)/365*F9 -> 6670529.8 | G8: =(Revenue!G22*Revenue!G6)/365*G9 -> 7705558 | H8: =(Revenue!H22*Revenue!H6)/365*H9 -> 8861939.7
A9: Creditor days | D9: =IF(D$1=1,Input!$B$62,MAX('Working Capital'!C9+Input!$B$63)) -> 65 | E9: =IF(E$1=1,Input!$B$62,MAX('Working Capital'!D9+Input!$B$63)) -> 68 | F9: =IF(F$1=1,Input!$B$62,MAX('Working Capital'!E9+Input!$B$63)) -> 71 | G9: =IF(G$1=1,Input!$B$62,MAX('Working Capital'!F9+Input!$B$63)) -> 74 | H9: =IF(H$1=1,Input!$B$62,MAX('Working Capital'!G9+Input!$B$63)) -> 77
A10: Outstanding expenses | D10: ='P&L'!D9/365*'Working Capital'!D11 -> 415561.64 | E10: ='P&L'!E9/365*'Working Capital'!E11 -> 614857.05 | F10: ='P&L'!F9/365*'Working Capital'!F11 -> 766283.43 | G10: ='P&L'!G9/365*'Working Capital'!G11 -> 898628.14 | H10: ='P&L'!H9/365*'Working Capital'!H11 -> 1029097.4
A11: Outstanding expenses days | D11: =Input!$B$64 -> 30 | E11: =Input!$B$64 -> 30 | F11: =Input!$B$64 -> 30 | G11: =Input!$B$64 -> 30 | H11: =Input!$B$64 -> 30

Sheet Balance Sheet
A1: Particulars | C1: 0 | D1: =C1+1 -> 1 | E1: =D1+1 -> 2 | F1: =E1+1 -> 3 | G1: =F1+1 -> 4 | H1: =G1+1 -> 5
A2: Year ending | D2: =EOMONTH(Input!B2,11) -> 45382 | E2: =EOMONTH(D2,12) -> 45747 | F2: =EOMONTH(E2,12) -> 46112 | G2: =EOMONTH(F2,12) -> 46477 | H2: =EOMONTH(G2,12) -> 46843
A3: Equity & Liabilities
A4: Equity
A5: Quasi equity | D5: =C5+'Cashflow Statement'!D34 -> 10914139 | E5: =D5+'Cashflow Statement'!E34 -> 14227012 | F5: =E5+'Cashflow Statement'!F34 -> 14227012 | G5: =F5+'Cashflow Statement'!G34 -> 14227012 | H5: =G5+'Cashflow Statement'!H34 -> 14227012
A6: Equity share capital | D6: =Input!$B$28 -> 1600000 | E6: =Input!$B$28 -> 1600000 | F6: =Input!$B$28 -> 1600000 | G6: =Input!$B$28 -> 1600000 | H6: =Input!$B$28 -> 1600000
A7: Reserves | D7: ='P&L'!D19 -> 3147480 | E7: ='P&L'!E19+'Balance Sheet'!D7 -> 8198910.1 | F7: ='P&L'!F19+'Balance Sheet'!E7 -> 15772223 | G7: ='P&L'!G19+'Balance Sheet'!F7 -> 25812516 | H7: ='P&L'!H19+'Balance Sheet'!G7 -> 38472866
A8: Total Equity | D8: =SUM(D5:D7) -> 15661619 | E8: =SUM(E5:E7) -> 24025922 | F8: =SUM(F5:F7) -> 31599235 | G8: =SUM(G5:G7) -> 41639528 | H8: =SUM(H5:H7) -> 54299878
A9: Liabilities
A10: Non-Current Liabilites
A11: Loan from bank | D11: ='Debt Schedule'!D6 -> 1500000 | E11: ='Debt Schedule'!E6 -> 1125000 | F11: ='Debt Schedule'!F6 -> 750000 | G11: ='Debt Schedule'!G6 -> 375000 | H11: ='Debt Schedule'!H6 -> 0
A13: Current Liabilities
A14: Creditors | D14: ='Working Capital'!D8 -> 4923616.4 | E14: ='Working Capital'!E8 -> 5746428.5 | F14: ='Working Capital'!F8 -> 6670529.8 | G14: ='Working Capital'!G8 -> 7705558 | H14: ='Working Capital'!H8 -> 8861939.7
A15: Outstanding expenses | D15: ='Working Capital'!D10 -> 415561.64 | E15: ='Working Capital'!E10 -> 614857.05 | F15: ='Working Capital'!F10 -> 766283.43 | G15: ='Working Capital'!G10 -> 898628.14 | H15: ='Working Capital'!H10 -> 1029097.4
A17: Total Liabilities | D17: =SUM(D14:D15,D11) -> 6839178.1 | E17: =SUM(E14:E15,E11) -> 7486285.5 | F17: =SUM(F14:F15,F11) -> 8186813.2 | G17: =SUM(G14:G15,G11) -> 8979186.1 | H17: =SUM(H14:H15,H11) -> 9891037.1
A18: Total (Liabilities & Equities) | D18: =SUM(D17,D8) -> 22500797 | E18: =SUM(E17,E8) -> 31512208 | F18: =SUM(F17,F8) -> 39786048 | G18: =SUM(G17,G8) -> 50618714 | H18: =SUM(H17,H8) -> 64190915
A20: Assets
A21: Non-Current assets
A22: Fixed assets (Net block)
A23: Equipments | D23: ='Fixed Assets'!D9 -> 1275000 | E23: ='Fixed Assets'!E9 -> 1050000 | F23: ='Fixed Assets'!F9 -> 1250000 | G23: ='Fixed Assets'!G9 -> 950000 | H23: ='Fixed Assets'!H9 -> 650000
A24: Land | D24: ='Fixed Assets'!D18 -> 180000 | E24: ='Fixed Assets'!E18 -> 160000 | F24: ='Fixed Assets'!F18 -> 140000 | G24: ='Fixed Assets'!G18 -> 120000 | H24: ='Fixed Assets'!H18 -> 100000
A25: Building | D25: ='Fixed Assets'!D27 -> 800000 | E25: ='Fixed Assets'!E27 -> 800000 | F25: ='Fixed Assets'!F27 -> 800000 | G25: ='Fixed Assets'!G27 -> 800000 | H25: ='Fixed Assets'!H27 -> 800000
A27: Current assets
A28: Debtors | D28: ='Working Capital'!D4 -> 3787397.3 | E28: ='Working Capital'!E4 -> 6022490.7 | F28: ='Working Capital'!F4 -> 7422268 | G28: ='Working Capital'!G4 -> 8409349 | H28: ='Working Capital'!H4 -> 9206112.2
A29: Closing stock | D29: =Revenue!D27 -> 16358400 | E29: =Revenue!E27 -> 23379717 | F29: =Revenue!F27 -> 25859674 | G29: =Revenue!G27 -> 26227247 | H29: =Revenue!H27 -> 25600337
A30: Cash | D30: ='Cashflow Statement'!D35 -> 100000 | E30: ='Cashflow Statement'!E35 -> 100000 | F30: ='Cashflow Statement'!F35 -> 4314105.7 | G30: ='Cashflow Statement'!G35 -> 14112118 | H30: ='Cashflow Statement'!H35 -> 27834465
A32: Total assets | D32: =SUM(D28:D30,D23:D25) -> 22500797 | E32: =SUM(E28:E30,E23:E25) -> 31512208 | F32: =SUM(F28:F30,F23:F25) -> 39786048 | G32: =SUM(G28:G30,G23:G25) -> 50618714 | H32: =SUM(H28:H30,H23:H25) -> 64190915
A33: Check | D33: =D32-D18 -> 0 | E33: =E32-E18 -> 0 | F33: =F32-F18 -> 0 | G33: =G32-G18 -> 0 | H33: =H32-H18 -> 0

Sheet Cashflow Statement
A1: Particulars | C1: 0 | D1: =C1+1 -> 1 | E1: =D1+1 -> 2 | F1: =E1+1 -> 3 | G1: =F1+1 -> 4 | H1: =G1+1 -> 5
A2: Year ending | D2: =EOMONTH(Input!B2,11) -> 45382 | E2: =EOMONTH(D2,12) -> 45747 | F2: =EOMONTH(E2,12) -> 46112 | G2: =EOMONTH(F2,12) -> 46477 | H2: =EOMONTH(G2,12) -> 46843
A3: Cashflow from Operating activities
A4: EAT | D4: 3147480 | E4: 7771430.9 | F4: 11651250 | G4: 15446605 | H4: 19477462
A5: Add: Non cash expenses
A6: Depreciation & Amortization | D6: ='P&L'!D11 -> 245000 | E6: ='P&L'!E11 -> 245000 | F6: ='P&L'!F11 -> 320000 | G6: ='P&L'!G11 -> 320000 | H6: ='P&L'!H11 -> 320000
A7: Add: Items to be considered under other activities | D7: ='P&L'!D13 -> 225000 | E7: ='P&L'!E13 -> 135000 | F7: ='P&L'!F13 -> 90000 | G7: ='P&L'!G13 -> 45000 | H7: ='P&L'!H13 -> 0
A8: Cash flow from Operations before impact of working capital | D8: =SUM(D4:D7) -> 3617480 | E8: =SUM(E4:E7) -> 8151430.9 | F8: =SUM(F4:F7) -> 12061250 | G8: =SUM(G4:G7) -> 15811605 | H8: =SUM(H4:H7) -> 19797462
A9: Changes Debtors | D9: =-('Balance Sheet'!D28-'Balance Sheet'!C28) -> -3787397.3 | E9: =-('Balance Sheet'!E28-'Balance Sheet'!D28) -> -2235093.4 | F9: =-('Balance Sheet'!F28-'Balance Sheet'!E28) -> -1399777.3 | G9: =-('Balance Sheet'!G28-'Balance Sheet'!F28) -> -987080.99 | H9: =-('Balance Sheet'!H28-'Balance Sheet'!G28) -> -796763.23
A10: Changes in Closing stock | D10: =-('Balance Sheet'!D29-'Balance Sheet'!C29) -> -16358400 | E10: =-('Balance Sheet'!E29-'Balance Sheet'!D29) -> -7021316.9 | F10: =-('Balance Sheet'!F29-'Balance Sheet'!E29) -> -2479957.3 | G10: =-('Balance Sheet'!G29-'Balance Sheet'!F29) -> -367572.77 | H10: =-('Balance Sheet'!H29-'Balance Sheet'!G29) -> 626909.48
A11: Changes Creditors | D11: =('Balance Sheet'!D14-'Balance Sheet'!C14) -> 4923616.4 | E11: =('Balance Sheet'!E14-'Balance Sheet'!D14) -> 822812.05 | F11: =('Balance Sheet'!F14-'Balance Sheet'!E14) -> 924101.26 | G11: =('Balance Sheet'!G14-'Balance Sheet'!F14) -> 1035028.2 | H11: =('Balance Sheet'!H14-'Balance Sheet'!G14) -> 1156381.7
A12: Changes Outstanding Expenses | D12: =('Balance Sheet'!D15-'Balance Sheet'!C15) -> 415561.64 | E12: =('Balance Sheet'!E15-'Balance Sheet'!D15) -> 199295.41 | F12: =('Balance Sheet'!F15-'Balance Sheet'!E15) -> 151426.38 | G12: =('Balance Sheet'!G15-'Balance Sheet'!F15) -> 132344.71 | H12: =('Balance Sheet'!H15-'Balance Sheet'!G15) -> 130469.25
A13: Cashflow from Operations | D13: =SUM(D8:D12) -> -11189139 | E13: =SUM(E8:E12) -> -82871.997 | F13: =SUM(F8:F12) -> 9257043.3 | G13: =SUM(G8:G12) -> 15624324 | H13: =SUM(H8:H12) -> 20914459
A15: Cashflow from Investing activities
A16: Purchases:
A17: Equipment | D17: =-('Fixed Assets'!D5) -> -1500000 | E17: =-('Fixed Assets'!E5) -> 0 | F17: =-('Fixed Assets'!F5) -> -500000 | G17: =-('Fixed Assets'!G5) -> 0 | H17: =-('Fixed Assets'!H5) -> 0
A18: Building | D18: =-('Fixed Assets'!D14) -> -200000 | E18: =-('Fixed Assets'!E14) -> 0 | F18: =-('Fixed Assets'!F14) -> 0 | G18: =-('Fixed Assets'!G14) -> 0 | H18: =-('Fixed Assets'!H14) -> 0
A19: Land | D19: =-('Fixed Assets'!D23) -> -800000 | E19: =-('Fixed Assets'!E23) -> 0 | F19: =-('Fixed Assets'!F23) -> 0 | G19: =-('Fixed Assets'!G23) -> 0 | H19: =-('Fixed Assets'!H23) -> 0
A20: Cashflow from Investing activities | D20: =SUM(D17:D19) -> -2500000 | E20: =SUM(E17:E19) -> 0 | F20: =SUM(F17:F19) -> -500000 | G20: =SUM(G17:G19) -> 0 | H20: =SUM(H17:H19) -> 0
A22: Cashflow from Financing activities
A23: Equity contribution | D23: =('Balance Sheet'!D6-'Balance Sheet'!C6) -> 1600000 | E23: ='Balance Sheet'!E6-'Balance Sheet'!D6 -> 0 | F23: ='Balance Sheet'!F6-'Balance Sheet'!E6 -> 0 | G23: ='Balance Sheet'!G6-'Balance Sheet'!F6 -> 0 | H23: ='Balance Sheet'!H6-'Balance Sheet'!G6 -> 0
A24: Debt taken | D24: ='Debt Schedule'!D4 -> 1500000 | E24: ='Debt Schedule'!E4 -> 0 | F24: ='Debt Schedule'!F4 -> 0 | G24: ='Debt Schedule'!G4 -> 0 | H24: ='Debt Schedule'!H4 -> 0
A25: Debt repaid | D25: =-'Debt Schedule'!D5 -> 0 | E25: =-'Debt Schedule'!E5 -> -375000 | F25: =-'Debt Schedule'!F5 -> -375000 | G25: =-'Debt Schedule'!G5 -> -375000 | H25: =-'Debt Schedule'!H5 -> -375000
A26: Interest paid | D26: =-'P&L'!D13 -> -225000 | E26: =-'P&L'!E13 -> -135000 | F26: =-'P&L'!F13 -> -90000 | G26: =-'P&L'!G13 -> -45000 | H26: =-'P&L'!H13 -> 0
A27: Dividend paid | D27: =-'P&L'!D18 -> 0 | E27: =-'P&L'!E18 -> -2720000.8 | F27: =-'P&L'!F18 -> -4077937.6 | G27: =-'P&L'!G18 -> -5406311.6 | H27: =-'P&L'!H18 -> -6817111.6
A28: Cashflow from Financing activities | D28: =SUM(D23:D27) -> 2875000 | E28: =SUM(E23:E27) -> -3230000.8 | F28: =SUM(F23:F27) -> -4542937.6 | G28: =SUM(G23:G27) -> -5826311.6 | H28: =SUM(H23:H27) -> -7192111.6
A30: Cashflow from all the activities during the year | D30: =SUM(D28,D20,D13) -> -10814139 | E30: =SUM(E28,E20,E13) -> -3312872.8 | F30: =SUM(F28,F20,F13) -> 4214105.7 | G30: =SUM(G28,G20,G13) -> 9798012.2 | H30: =SUM(H28,H20,H13) -> 13722347
A31: Add: Opening balance of cash | D31: =C32 -> 0 | E31: =D35 -> 100000 | F31: =E35 -> 100000 | G31: =F35 -> 4314105.7 | H31: =G35 -> 14112118
A32: Closing Balance of cash before the introduction of Quasi equity | D32: =D30+D31 -> -10814139 | E32: =E30+E31 -> -3212872.8 | F32: =F30+F31 -> 4314105.7 | G32: =G30+G31 -> 14112118 | H32: =H30+H31 -> 27834465
A33: Minimum cash balance to be maintained | D33: 100000 | E33: 100000 | F33: 100000 | G33: 100000 | H33: 100000
A34: Equity capital to be introduced | D34: =IF(D32<0,ABS(D32)+D33,0) -> 10914139 | E34: =IF(E32<0,ABS(E32)+E33,0) -> 3312872.8 | F34: =IF(F32<0,ABS(F32)+F33,0) -> 0 | G34: =IF(G32<0,ABS(G32)+G33,0) -> 0 | H34: =IF(H32<0,ABS(H32)+H33,0) -> 0
A35: Closing Balance | D35: =D32+D34 -> 100000 | E35: =E32+E34 -> 100000 | F35: =F32+F34 -> 4314105.7 | G35: =G32+G34 -> 14112118 | H35: =H32+H34 -> 27834465

Sheet Analysis
A1: Particulars | C1: 0 | D1: =C1+1 -> 1 | E1: =D1+1 -> 2 | F1: =E1+1 -> 3 | G1: =F1+1 -> 4 | H1: =G1+1 -> 5
A2: Year ending | D2: =EOMONTH(Input!B2,11) -> 45382 | E2: =EOMONTH(D2,12) -> 45747 | F2: =EOMONTH(E2,12) -> 46112 | G2: =EOMONTH(F2,12) -> 46477 | H2: =EOMONTH(G2,12) -> 46843
A3: Free cashflow calculation | B3: Rs.
A4: EBIT | B4: Rs. | D4: ='P&L'!D12 -> 4721400 | E4: ='P&L'!E12 -> 11237044 | F4: ='P&L'!F12 -> 16734643 | G4: ='P&L'!G12 -> 22111578 | H4: ='P&L'!H12 -> 27824945
A5: Less: Taxes of business | B5: Rs. | D5: =D4*Input!$B$57 -> 1416420 | E5: =E4*Input!$B$57 -> 3371113.2 | F5: =F4*Input!$B$57 -> 5020393 | G5: =G4*Input!$B$57 -> 6633473.4 | H5: =H4*Input!$B$57 -> 8347483.6
A6: NOPAT (PAT of business) | B6: Rs. | D6: =D4-D5 -> 3304980 | E6: =E4-E5 -> 7865930.9 | F6: =F4-F5 -> 11714250 | G6: =G4-G5 -> 15478105 | H6: =H4-H5 -> 19477462
A7: Less: Capital expenditure | B7: Rs. | D7: =SUM('Cashflow Statement'!D17:D19) -> -2500000 | E7: =SUM('Cashflow Statement'!E17:E19) -> 0 | F7: =SUM('Cashflow Statement'!F17:F19) -> -500000 | G7: =SUM('Cashflow Statement'!G17:G19) -> 0 | H7: =SUM('Cashflow Statement'!H17:H19) -> 0
A8: Add: Depreciation & Amortization | B8: Rs. | D8: ='Cashflow Statement'!D6 -> 245000 | E8: ='Cashflow Statement'!E6 -> 245000 | F8: ='Cashflow Statement'!F6 -> 320000 | G8: ='Cashflow Statement'!G6 -> 320000 | H8: ='Cashflow Statement'!H6 -> 320000
A9: Add/Less Changes in working capital | B9: Rs. | D9: =SUM('Cashflow Statement'!D9:D12) -> -14806619 | E9: =SUM('Cashflow Statement'!E9:E12) -> -8234302.9 | F9: =SUM('Cashflow Statement'!F9:F12) -> -2804206.9 | G9: =SUM('Cashflow Statement'!G9:G12) -> -187280.84 | H9: =SUM('Cashflow Statement'!H9:H12) -> 1116997.2
A10: Free cashflow to firm (FCFF) | B10: Rs. | D10: =SUM(D6:D9) -> -13756639 | E10: =SUM(E6:E9) -> -123372 | F10: =SUM(F6:F9) -> 8730043.3 | G10: =SUM(G6:G9) -> 15610824 | H10: =SUM(H6:H9) -> 20914459
A11: Less: Interest after tax | B11: Rs. | D11: =-'P&L'!D13*(1-Input!$B$57) -> -157500 | E11: =-'P&L'!E13*(1-Input!$B$57) -> -94500 | F11: =-'P&L'!F13*(1-Input!$B$57) -> -63000 | G11: =-'P&L'!G13*(1-Input!$B$57) -> -31500 | H11: =-'P&L'!H13*(1-Input!$B$57) -> 0
A12: Add/Less: Debt taken/repaid | B12: Rs. | D12: =SUM('Cashflow Statement'!D24:D25) -> 1500000 | E12: =SUM('Cashflow Statement'!E24:E25) -> -375000 | F12: =SUM('Cashflow Statement'!F24:F25) -> -375000 | G12: =SUM('Cashflow Statement'!G24:G25) -> -375000 | H12: =SUM('Cashflow Statement'!H24:H25) -> -375000
A13: Free cashflow to Equity | B13: Rs. | D13: =SUM(D10:D12) -> -12414139 | E13: =SUM(E10:E12) -> -592872 | F13: =SUM(F10:F12) -> 8292043.3 | G13: =SUM(G10:G12) -> 15204324 | H13: =SUM(H10:H12) -> 20539459

Sheet Explanation
C10: Accural Principal | E10: Sales
C11: Matching principal | E11: Less: COGS (Direct cost)
E12: GP
E13: Less: Indirect cost
E14: SG&A
E15: EBITDA | H15: Earning before interest, tax, depriciation and amortization
E16: Less: Dep. And Amortization
E17: EBIT (Operating Profit) | H17: Earning before interest and tax
E18: Less: Int.
E19: EBT | H19: Earning before tax
E20: Less: Taxes
E21: EAT (Net Profit) | H21: Earning after tax
E22: Less: Dividend
E23: Transfer to reserve
